<?xml version="1.0" ?>
<robot name="pacifista" xmlns:xacro="http://www.ros.org/wiki/xacro">

<xacro:include filename="$(find pacifista_description)/urdf/materials.xacro" />
<xacro:include filename="$(find pacifista_description)/urdf/pacifista.trans" />
<xacro:include filename="$(find pacifista_description)/urdf/pacifista.gazebo" />

<link name="base_footprint"/>
  <material name="white">
    <color rgba="0 0 0 1"/>
  </material>
<link name="base_link">
  <inertial>
    <origin xyz="0.06416645884835959 -9.350742402602919e-14 0.04953820388310092" rpy="0 0 0"/>
    <mass value="10.289943238273888"/>
    <inertia ixx="0.0667232" iyy="0.4306062" izz="0.4824065" ixy="-0.0" iyz="0.0" ixz="-0.0003325"/>
  </inertial>
  <visual>
    <origin xyz="0 0 0" rpy="0 0 0"/>
    <geometry>
      <mesh filename="package://pacifista_description/meshes/base_link.stl" scale="0.001 0.001 0.001"/>
    </geometry>
    <material name="silver"/>
  </visual>
  <collision>
    <origin xyz="0 0 0" rpy="0 0 0"/>
    <geometry>
      <mesh filename="package://pacifista_description/meshes/base_link.stl" scale="0.001 0.001 0.001"/>
    </geometry>
  </collision>
</link>

<link name="wh_r_frwd_1">
  <inertial>
    <origin xyz="9.053519118396025e-06 0.015003093731232209 -2.416482632122685e-05" rpy="0 0 0"/>
    <mass value="1.1747535420042476"/>
    <inertia ixx="0.0031" iyy="0.00603" izz="0.0031" ixy="-0.0" iyz="0.0" ixz="0.0"/>
  </inertial>
  <visual>
    <origin xyz="0.225 -0.166 -0.037249" rpy="0 0 0"/>
    <geometry>
      <mesh filename="package://pacifista_description/meshes/wh_r_frwd_1.stl" scale="0.001 0.001 0.001"/>
    </geometry>
    <material name="silver"/>
  </visual>
  <collision>
    <origin xyz="0.225 -0.166 -0.037249" rpy="0 0 0"/>
    <geometry>
      <mesh filename="package://pacifista_description/meshes/wh_r_frwd_1.stl" scale="0.001 0.001 0.001"/>
    </geometry>
  </collision>
</link>

<link name="wh_l_frwd_1">
  <inertial>
    <origin xyz="-7.178188420192688e-06 -0.01500000221141995 -1.0932791507246853e-05" rpy="0 0 0"/>
    <mass value="1.17474361934232"/>
    <inertia ixx="0.0031" iyy="0.00602" izz="0.0031" ixy="0.0" iyz="0.0" ixz="-0.0"/>
  </inertial>
  <visual>
    <origin xyz="0.225 0.166 -0.037249" rpy="0 0 0"/>
    <geometry>
      <mesh filename="package://pacifista_description/meshes/wh_l_frwd_1.stl" scale="0.001 0.001 0.001"/>
    </geometry>
    <material name="silver"/>
  </visual>
  <collision>
    <origin xyz="0.225 0.166 -0.037249" rpy="0 0 0"/>
    <geometry>
      <mesh filename="package://pacifista_description/meshes/wh_l_frwd_1.stl" scale="0.001 0.001 0.001"/>
    </geometry>
  </collision>
</link>

<link name="wh_r_bck_1">
  <inertial>
    <origin xyz="7.178190349677038e-06 0.01500000221328543 -1.0932791713019752e-05" rpy="0 0 0"/>
    <mass value="1.1747436193421128"/>
    <inertia ixx="0.0031" iyy="0.00602" izz="0.0031" ixy="0.0" iyz="-0.0" ixz="0.0"/>
  </inertial>
  <visual>
    <origin xyz="-0.3848 -0.166 -0.037249" rpy="0 0 0"/>
    <geometry>
      <mesh filename="package://pacifista_description/meshes/wh_r_bck_1.stl" scale="0.001 0.001 0.001"/>
    </geometry>
    <material name="silver"/>
  </visual>
  <collision>
    <origin xyz="-0.3848 -0.166 -0.037249" rpy="0 0 0"/>
    <geometry>
      <mesh filename="package://pacifista_description/meshes/wh_r_bck_1.stl" scale="0.001 0.001 0.001"/>
    </geometry>
  </collision>
</link>

<link name="wh_l_bck_1">
  <inertial>
    <origin xyz="-7.178190368717363e-06 -0.015000002210074415 -1.0932791498503847e-05" rpy="0 0 0"/>
    <mass value="1.1747436193421126"/>
    <inertia ixx="0.0031" iyy="0.00602" izz="0.0031" ixy="0.0" iyz="0.0" ixz="-0.0"/>
  </inertial>
  <visual>
    <origin xyz="-0.3848 0.166 -0.037249" rpy="0 0 0"/>
    <geometry>
      <mesh filename="package://pacifista_description/meshes/wh_l_bck_1.stl" scale="0.001 0.001 0.001"/>
    </geometry>
    <material name="silver"/>
  </visual>
  <collision>
    <origin xyz="-0.3848 0.166 -0.037249" rpy="0 0 0"/>
    <geometry>
      <mesh filename="package://pacifista_description/meshes/wh_l_bck_1.stl" scale="0.001 0.001 0.001"/>
    </geometry>
  </collision>
</link>

<link name="lidar_1">
  <inertial>
    <origin xyz="-5.537237335317968e-15 6.44995168386231e-14 0.01500029577549461" rpy="0 0 0"/>
    <mass value="0.9063102106524822"/>
    <inertia ixx="0.000346" iyy="0.000346" izz="0.000555" ixy="-0.0" iyz="-0.0" ixz="-0.0"/>
  </inertial>
  <visual>
    <origin xyz="-0.0914 -0.0 -0.152352" rpy="0 0 0"/>
    <geometry>
      <mesh filename="package://pacifista_description/meshes/lidar_1.stl" scale="0.001 0.001 0.001"/>
    </geometry>
    <material name="silver"/>
  </visual>
  <collision>
    <origin xyz="-0.0914 -0.0 -0.152352" rpy="0 0 0"/>
    <geometry>
      <mesh filename="package://pacifista_description/meshes/lidar_1.stl" scale="0.001 0.001 0.001"/>
    </geometry>
  </collision>
</link>
 <joint name="base_joint" type="fixed">
		<parent link="base_footprint" />
		<child link="base_link" />
		<origin xyz="0 0 0.080198"/>
	</joint>
<joint name="Rev1" type="continuous">
  <origin xyz="-0.225 0.166 0.037249" rpy="0 0 0"/>
  <parent link="base_link"/>
  <child link="wh_r_frwd_1"/>
  <axis xyz="-0.0 1.0 -0.0"/>
</joint>

<joint name="Rev2" type="continuous">
  <origin xyz="-0.225 -0.166 0.037249" rpy="0 0 0"/>
  <parent link="base_link"/>
  <child link="wh_l_frwd_1"/>
  <axis xyz="-0.0 1.0 -0.0"/>
</joint>

<joint name="Rev3" type="continuous">
  <origin xyz="0.3848 0.166 0.037249" rpy="0 0 0"/>
  <parent link="base_link"/>
  <child link="wh_r_bck_1"/>
  <axis xyz="-0.0 1.0 -0.0"/>
</joint>

<joint name="Rev4" type="continuous">
  <origin xyz="0.3848 -0.166 0.037249" rpy="0 0 0"/>
  <parent link="base_link"/>
  <child link="wh_l_bck_1"/>
  <axis xyz="-0.0 1.0 -0.0"/>
</joint>

<joint name="Rigid_16" type="fixed">
  <origin xyz="0.0914 0.0 0.152352" rpy="0 0 0"/>
  <parent link="base_link"/>
  <child link="lidar_1"/>
</joint>

</robot>
